<?xml version="1.0" encoding="utf-8"?>
<!-- This URDF was automatically created by SolidWorks to URDF Exporter! Originally created by Stephen Brawner (brawner@gmail.com) 
     Commit Version: 1.5.1-0-g916b5db  Build Version: 1.5.7152.31018
     For more information, please see http://wiki.ros.org/sw_urdf_exporter -->
<robot
  name="astro_description">
  <link name="dummy"/>
  <joint name="base_joint" type="fixed">
    <parent link="dummy"/>
    <child link="base_link"/>
    <origin xyz="0.0 0.0 0.010" rpy="0 0 0"/>
  </joint>
  
  <link
    name="base_link">
    <inertial>
      <origin
        xyz="8.31153464457157E-18 6.50618032034739E-18 5.0603624713813E-18"
        rpy="0 0 0" />
      <mass
        value="4.68680310101314" />
      <inertia
        ixx="0.0154717864738765"
        ixy="-1.44964753828898E-18"
        ixz="1.09665913846752E-18"
        iyy="0.0330737703955579"
        iyz="8.32585455221295E-20"
        izz="0.0414712634973384" />
    </inertial>
    <visual>
      <origin
        xyz="0 0 0"
        rpy="0 0 0" />
      <geometry>
        <mesh
          filename="package://astro_description/meshes/base_link.STL" />
      </geometry>
      <material
        name="">
        <color
          rgba="0.615686274509804 0.811764705882353 0.929411764705882 1" />
      </material>
    </visual>
    <collision>
      <origin
        xyz="0 0 0"
        rpy="0 0 0" />
      <geometry>
        <mesh
          filename="package://astro_description/meshes/base_link.STL" />
      </geometry>
    </collision>
  </link>
  <link
    name="hip_0">
    <inertial>
      <origin
        xyz="0 -1.38777878078145E-17 1.25816239120847E-20"
        rpy="0 0 0" />
      <mass
        value="0.246223359229195" />
      <inertia
        ixx="0.000165256724841001"
        ixy="-9.05104722009984E-15"
        ixz="-1.66129314216246E-14"
        iyy="0.000278470026411962"
        iyz="-1.73436802029533E-14"
        izz="0.000163858703021357" />
    </inertial>
    <visual>
      <origin
        xyz="0 0 0"
        rpy="0 0 0" />
      <geometry>
        <mesh
          filename="package://astro_description/meshes/hip_0.STL" />
      </geometry>
      <material
        name="">
        <color
          rgba="0.615686274509804 0.811764705882353 0.929411764705882 1" />
      </material>
    </visual>
    <collision>
      <origin
        xyz="0 0 0"
        rpy="0 0 0" />
      <geometry>
        <mesh
          filename="package://astro_description/meshes/hip_0.STL" />
      </geometry>
    </collision>
  </link>
  <joint
    name="hip_0"
    type="revolute">
    <origin
      xyz="0.185 0.065 0"
      rpy="0 0 0" />
    <parent
      link="base_link" />
    <child
      link="hip_0" />
    <axis
      xyz="-1 0 0" />
    <limit
      lower="-3.14"
      upper="3.14"
      effort="10"
      velocity="10" />
  </joint>
  <link
    name="shoulder_0">
    <inertial>
      <origin
        xyz="4.06795680474303E-10 0.0158652706913515 -0.0518927213529733"
        rpy="0 0 0" />
      <mass
        value="0.508100774960777" />
      <inertia
        ixx="0.00253510428613682"
        ixy="-1.80683476493991E-11"
        ixz="-2.00076175747246E-11"
        iyy="0.00255511245596087"
        iyz="0.000407766188388369"
        izz="0.000348890325766077" />
    </inertial>
    <visual>
      <origin
        xyz="0 0 0"
        rpy="0 0 0" />
      <geometry>
        <mesh
          filename="package://astro_description/meshes/shoulder_0.STL" />
      </geometry>
      <material
        name="">
        <color
          rgba="0.615686274509804 0.811764705882353 0.929411764705882 1" />
      </material>
    </visual>
    <collision>
      <origin
        xyz="0 0 0"
        rpy="0 0 0" />
      <geometry>
        <mesh
          filename="package://astro_description/meshes/shoulder_0.STL" />
      </geometry>
    </collision>
  </link>
  <joint
    name="shoulder_0"
    type="revolute">
    <origin
      xyz="0 0.0349999999353767 0"
      rpy="0 0 0" />
    <parent
      link="hip_0" />
    <child
      link="shoulder_0" />
    <axis
      xyz="0 1 0" />
    <limit
      lower="-3.14"
      upper="3.14"
      effort="10"
      velocity="10" />
  </joint>
  <link
    name="knee_0">
    <inertial>
      <origin
        xyz="2.3577252546203E-05 -2.77555756156289E-17 -0.0854767786481249"
        rpy="0 0 0" />
      <mass
        value="0.0550655915530228" />
      <inertia
        ixx="0.000108166100210968"
        ixy="9.08465366075516E-22"
        ixz="-3.77066822641529E-08"
        iyy="0.000109318668697255"
        iyz="1.43882130258396E-20"
        izz="4.74934642586929E-06" />
    </inertial>
    <visual>
      <origin
        xyz="0 0 0"
        rpy="0 0 0" />
      <geometry>
        <mesh
          filename="package://astro_description/meshes/knee_0.STL" />
      </geometry>
      <material
        name="">
        <color
          rgba="0.615686274509804 0.811764705882353 0.929411764705882 1" />
      </material>
    </visual>
    <collision>
      <origin
        xyz="0 0 0"
        rpy="0 0 0" />
      <geometry>
        <mesh
          filename="package://astro_description/meshes/knee_0.STL" />
      </geometry>
    </collision>
  </link>
  <joint
    name="knee_0"
    type="revolute">
    <origin
      xyz="0 0.0314999999999999 -0.1875"
      rpy="0 0 0" />
    <parent
      link="shoulder_0" />
    <child
      link="knee_0" />
    <axis
      xyz="0 -1 0" />
    <limit
      lower="-3.14"
      upper="3.14"
      effort="10"
      velocity="10" />
  </joint>
  <link
    name="toe_0">
    <inertial>
      <origin
        xyz="2.95606317202157E-11 9.95770133016549E-12 -0.00105178196616629"
        rpy="0 0 0" />
      <mass
        value="0.00341340894922415" />
      <inertia
        ixx="1.37512731322582E-07"
        ixy="3.15030137833387E-16"
        ixz="-8.62139511434755E-16"
        iyy="1.34732164237532E-07"
        iyz="-2.80019540660074E-16"
        izz="1.56709984508881E-07" />
    </inertial>
    <visual>
      <origin
        xyz="0 0 0"
        rpy="0 0 0" />
      <geometry>
        <mesh
          filename="package://astro_description/meshes/toe_0.STL" />
      </geometry>
      <material
        name="">
        <color
          rgba="1 0 0 1" />
      </material>
    </visual>
    <collision>
      <origin
        xyz="0 0 0"
        rpy="0 0 0" />
      <geometry>
        <mesh
          filename="package://astro_description/meshes/toe_0.STL" />
      </geometry>
    </collision>
  </link>
  <joint
    name="toe_0"
    type="fixed">
    <origin
      xyz="0 0 -0.19"
      rpy="0 0 0" />
    <parent
      link="knee_0" />
    <child
      link="toe_0" />
    <axis
      xyz="0 0 0" />
    <limit
      lower="-3.14"
      upper="3.14"
      effort="0"
      velocity="0" />
  </joint>
  <link
    name="hip_1">
    <inertial>
      <origin
        xyz="2.77555756156289E-17 1.38777878078145E-17 3.30036792602533E-20"
        rpy="0 0 0" />
      <mass
        value="0.246223359229195" />
      <inertia
        ixx="0.000165256724841001"
        ixy="9.05105986575477E-15"
        ixz="1.66129315864524E-14"
        iyy="0.000278470026411962"
        iyz="-1.73437001365424E-14"
        izz="0.000163858703021357" />
    </inertial>
    <visual>
      <origin
        xyz="0 0 0"
        rpy="0 0 0" />
      <geometry>
        <mesh
          filename="package://astro_description/meshes/hip_1.STL" />
      </geometry>
      <material
        name="">
        <color
          rgba="0.615686274509804 0.811764705882353 0.929411764705882 1" />
      </material>
    </visual>
    <collision>
      <origin
        xyz="0 0 0"
        rpy="0 0 0" />
      <geometry>
        <mesh
          filename="package://astro_description/meshes/hip_1.STL" />
      </geometry>
    </collision>
  </link>
  <joint
    name="hip_1"
    type="revolute">
    <origin
      xyz="0.185 -0.065 0"
      rpy="0 0 0" />
    <parent
      link="base_link" />
    <child
      link="hip_1" />
    <axis
      xyz="1 0 0" />
    <limit
      lower="-3.14"
      upper="3.14"
      effort="10"
      velocity="10" />
  </joint>
  <link
    name="shoulder_1">
    <inertial>
      <origin
        xyz="-4.06795652718728E-10 -0.0158652706913514 -0.0518927213529733"
        rpy="0 0 0" />
      <mass
        value="0.508100774960777" />
      <inertia
        ixx="0.00253510428613682"
        ixy="-1.80683477464773E-11"
        ixz="2.00076171968531E-11"
        iyy="0.00255511245596086"
        iyz="-0.000407766188388369"
        izz="0.000348890325766076" />
    </inertial>
    <visual>
      <origin
        xyz="0 0 0"
        rpy="0 0 0" />
      <geometry>
        <mesh
          filename="package://astro_description/meshes/shoulder_1.STL" />
      </geometry>
      <material
        name="">
        <color
          rgba="0.615686274509804 0.811764705882353 0.929411764705882 1" />
      </material>
    </visual>
    <collision>
      <origin
        xyz="0 0 0"
        rpy="0 0 0" />
      <geometry>
        <mesh
          filename="package://astro_description/meshes/shoulder_1.STL" />
      </geometry>
    </collision>
  </link>
  <joint
    name="shoulder_1"
    type="revolute">
    <origin
      xyz="0 -0.0349999999353766 0"
      rpy="0 0 0" />
    <parent
      link="hip_1" />
    <child
      link="shoulder_1" />
    <axis
      xyz="0 -1 0" />
    <limit
      lower="-3.14"
      upper="3.14"
      effort="10"
      velocity="10" />
  </joint>
  <link
    name="knee_1">
    <inertial>
      <origin
        xyz="-2.35772525461475E-05 -2.77555756156289E-17 -0.085476778648125"
        rpy="0 0 0" />
      <mass
        value="0.0550655915530228" />
      <inertia
        ixx="0.000108166100210968"
        ixy="1.95711519985102E-21"
        ixz="3.77066822642154E-08"
        iyy="0.000109318668697255"
        iyz="-1.11492990036179E-20"
        izz="4.74934642586929E-06" />
    </inertial>
    <visual>
      <origin
        xyz="0 0 0"
        rpy="0 0 0" />
      <geometry>
        <mesh
          filename="package://astro_description/meshes/knee_1.STL" />
      </geometry>
      <material
        name="">
        <color
          rgba="0.615686274509804 0.811764705882353 0.929411764705882 1" />
      </material>
    </visual>
    <collision>
      <origin
        xyz="0 0 0"
        rpy="0 0 0" />
      <geometry>
        <mesh
          filename="package://astro_description/meshes/knee_1.STL" />
      </geometry>
    </collision>
  </link>
  <joint
    name="knee_1"
    type="revolute">
    <origin
      xyz="0 -0.0315000000000001 -0.1875"
      rpy="0 0 0" />
    <parent
      link="shoulder_1" />
    <child
      link="knee_1" />
    <axis
      xyz="0 1 0" />
    <limit
      lower="-3.14"
      upper="3.14"
      effort="10"
      velocity="10" />
  </joint>
  <link
    name="toe_1">
    <inertial>
      <origin
        xyz="-2.95606039646401E-11 -9.95770133016549E-12 -0.00105178196616634"
        rpy="0 0 0" />
      <mass
        value="0.00341340894922415" />
      <inertia
        ixx="1.37512731322582E-07"
        ixy="3.15030139835466E-16"
        ixz="8.62139516591554E-16"
        iyy="1.34732164237532E-07"
        iyz="2.80019542233771E-16"
        izz="1.56709984508881E-07" />
    </inertial>
    <visual>
      <origin
        xyz="0 0 0"
        rpy="0 0 0" />
      <geometry>
        <mesh
          filename="package://astro_description/meshes/toe_1.STL" />
      </geometry>
      <material
        name="">
        <color
          rgba="1 0 0 1" />
      </material>
    </visual>
    <collision>
      <origin
        xyz="0 0 0"
        rpy="0 0 0" />
      <geometry>
        <mesh
          filename="package://astro_description/meshes/toe_1.STL" />
      </geometry>
    </collision>
  </link>
  <joint
    name="toe_1"
    type="fixed">
    <origin
      xyz="0 0 -0.19"
      rpy="0 0 0" />
    <parent
      link="knee_1" />
    <child
      link="toe_1" />
    <axis
      xyz="0 0 0" />
  </joint>
  <link
    name="hip_2">
    <inertial>
      <origin
        xyz="0 1.38777878078145E-17 5.79034700593245E-20"
        rpy="0 0 0" />
      <mass
        value="0.246223359229195" />
      <inertia
        ixx="0.000165256724841001"
        ixy="9.05104333115616E-15"
        ixz="1.66129315189461E-14"
        iyy="0.000278470026411962"
        iyz="-1.73436818613365E-14"
        izz="0.000163858703021357" />
    </inertial>
    <visual>
      <origin
        xyz="0 0 0"
        rpy="0 0 0" />
      <geometry>
        <mesh
          filename="package://astro_description/meshes/hip_2.STL" />
      </geometry>
      <material
        name="">
        <color
          rgba="0.615686274509804 0.811764705882353 0.929411764705882 1" />
      </material>
    </visual>
    <collision>
      <origin
        xyz="0 0 0"
        rpy="0 0 0" />
      <geometry>
        <mesh
          filename="package://astro_description/meshes/hip_2.STL" />
      </geometry>
    </collision>
  </link>
  <joint
    name="hip_2"
    type="revolute">
    <origin
      xyz="-0.185 -0.065 0"
      rpy="0 0 0" />
    <parent
      link="base_link" />
    <child
      link="hip_2" />
    <axis
      xyz="1 0 0" />
    <limit
      lower="-3.14"
      upper="3.14"
      effort="10"
      velocity="0" />
  </joint>
  <link
    name="shoulder_2">
    <inertial>
      <origin
        xyz="-4.06795680474303E-10 -0.0158652706913515 -0.0518927213529733"
        rpy="0 0 0" />
      <mass
        value="0.508100774960777" />
      <inertia
        ixx="0.00253510428613682"
        ixy="-1.80683477480077E-11"
        ixz="2.00076171935163E-11"
        iyy="0.00255511245596086"
        iyz="-0.000407766188388369"
        izz="0.000348890325766076" />
    </inertial>
    <visual>
      <origin
        xyz="0 0 0"
        rpy="0 0 0" />
      <geometry>
        <mesh
          filename="package://astro_description/meshes/shoulder_2.STL" />
      </geometry>
      <material
        name="">
        <color
          rgba="0.615686274509804 0.811764705882353 0.929411764705882 1" />
      </material>
    </visual>
    <collision>
      <origin
        xyz="0 0 0"
        rpy="0 0 0" />
      <geometry>
        <mesh
          filename="package://astro_description/meshes/shoulder_2.STL" />
      </geometry>
    </collision>
  </link>
  <joint
    name="shoulder_2"
    type="revolute">
    <origin
      xyz="0 -0.0349999999353766 0"
      rpy="0 0 0" />
    <parent
      link="hip_2" />
    <child
      link="shoulder_2" />
    <axis
      xyz="0 1 0" />
    <limit
      lower="-3.14"
      upper="3.14"
      effort="10"
      velocity="10" />
  </joint>
  <link
    name="knee_2">
    <inertial>
      <origin
        xyz="-2.3577252546203E-05 -2.77555756156289E-17 -0.085476778648125"
        rpy="0 0 0" />
      <mass
        value="0.0550655915530229" />
      <inertia
        ixx="0.000108166100210968"
        ixy="1.44041189360952E-22"
        ixz="3.77066822641946E-08"
        iyy="0.000109318668697255"
        iyz="9.00219991143379E-21"
        izz="4.7493464258693E-06" />
    </inertial>
    <visual>
      <origin
        xyz="0 0 0"
        rpy="0 0 0" />
      <geometry>
        <mesh
          filename="package://astro_description/meshes/knee_2.STL" />
      </geometry>
      <material
        name="">
        <color
          rgba="0.615686274509804 0.811764705882353 0.929411764705882 1" />
      </material>
    </visual>
    <collision>
      <origin
        xyz="0 0 0"
        rpy="0 0 0" />
      <geometry>
        <mesh
          filename="package://astro_description/meshes/knee_2.STL" />
      </geometry>
    </collision>
  </link>
  <joint
    name="knee_2"
    type="revolute">
    <origin
      xyz="0 -0.0315 -0.1875"
      rpy="0 0 0" />
    <parent
      link="shoulder_2" />
    <child
      link="knee_2" />
    <axis
      xyz="0 1 0" />
    <limit
      lower="-3.14"
      upper="3.14"
      effort="10"
      velocity="10" />
  </joint>
  <link
    name="toe_2">
    <inertial>
      <origin
        xyz="-2.95607982536694E-11 -0.263000000009958 -0.00105178196616645"
        rpy="0 0 0" />
      <mass
        value="0.00341340894922415" />
      <inertia
        ixx="1.37512731322582E-07"
        ixy="3.15030147553305E-16"
        ixz="8.62139524687812E-16"
        iyy="1.34732164237532E-07"
        iyz="2.80019554816043E-16"
        izz="1.56709984508881E-07" />
    </inertial>
    <visual>
      <origin
        xyz="0 0.263000000009958 0"
        rpy="0 0 0" />
      <geometry>
        <mesh
          filename="package://astro_description/meshes/toe_2.STL" />
      </geometry>
      <material
        name="">
        <color
          rgba="1 0 0 1" />
      </material>
    </visual>
    <collision>
      <origin
        xyz="0 0.263000000009958 0"
        rpy="0 0 0" />
      <geometry>
        <mesh
          filename="package://astro_description/meshes/toe_2.STL" />
      </geometry>
    </collision>
  </link>
  <joint
    name="toe_2"
    type="fixed">
    <origin
      xyz="0 0 -0.19"
      rpy="0 0 0" />
    <parent
      link="knee_2" />
    <child
      link="toe_2" />
    <axis
      xyz="0 0 0" />
  </joint>
  <link
    name="hip_3">
    <inertial>
      <origin
        xyz="0 -1.38777878078145E-17 -2.09908971156636E-19"
        rpy="0 0 0" />
      <mass
        value="0.246223359229195" />
      <inertia
        ixx="0.000165256724841001"
        ixy="-9.05106570189378E-15"
        ixz="-1.66129315081456E-14"
        iyy="0.000278470026411962"
        iyz="-1.73436830128447E-14"
        izz="0.000163858703021357" />
    </inertial>
    <visual>
      <origin
        xyz="0 0 0"
        rpy="0 0 0" />
      <geometry>
        <mesh
          filename="package://astro_description/meshes/hip_3.STL" />
      </geometry>
      <material
        name="">
        <color
          rgba="0.615686274509804 0.811764705882353 0.929411764705882 1" />
      </material>
    </visual>
    <collision>
      <origin
        xyz="0 0 0"
        rpy="0 0 0" />
      <geometry>
        <mesh
          filename="package://astro_description/meshes/hip_3.STL" />
      </geometry>
    </collision>
  </link>
  <joint
    name="hip_3"
    type="revolute">
    <origin
      xyz="-0.185 0.065 0"
      rpy="0 0 0" />
    <parent
      link="base_link" />
    <child
      link="hip_3" />
    <axis
      xyz="-1 0 0" />
    <limit
      lower="-3.14"
      upper="3.14"
      effort="10"
      velocity="10" />
  </joint>
  <link
    name="shoulder_3">
    <inertial>
      <origin
        xyz="4.06795680474303E-10 0.0158652706913514 -0.0518927213529732"
        rpy="0 0 0" />
      <mass
        value="0.508100774960776" />
      <inertia
        ixx="0.00253510428613682"
        ixy="-1.8068347626344E-11"
        ixz="-2.00076178633419E-11"
        iyy="0.00255511245596086"
        iyz="0.000407766188388369"
        izz="0.000348890325766076" />
    </inertial>
    <visual>
      <origin
        xyz="0 0 0"
        rpy="0 0 0" />
      <geometry>
        <mesh
          filename="package://astro_description/meshes/shoulder_3.STL" />
      </geometry>
      <material
        name="">
        <color
          rgba="0.615686274509804 0.811764705882353 0.929411764705882 1" />
      </material>
    </visual>
    <collision>
      <origin
        xyz="0 0 0"
        rpy="0 0 0" />
      <geometry>
        <mesh
          filename="package://astro_description/meshes/shoulder_3.STL" />
      </geometry>
    </collision>
  </link>
  <joint
    name="shoulder_3"
    type="revolute">
    <origin
      xyz="0 0.0349999999353766 0"
      rpy="0 0 0" />
    <parent
      link="hip_3" />
    <child
      link="shoulder_3" />
    <axis
      xyz="0 1 0" />
    <limit
      lower="-3.14"
      upper="3.14"
      effort="10"
      velocity="10" />
  </joint>
  <link
    name="knee_3">
    <inertial>
      <origin
        xyz="2.3577252546203E-05 0 -0.0854767786481249"
        rpy="0 0 0" />
      <mass
        value="0.0550655915530229" />
      <inertia
        ixx="0.000108166100210968"
        ixy="3.25909368174477E-22"
        ixz="-3.77066822641636E-08"
        iyy="0.000109318668697255"
        iyz="1.3066358238985E-20"
        izz="4.7493464258693E-06" />
    </inertial>
    <visual>
      <origin
        xyz="0 0 0"
        rpy="0 0 0" />
      <geometry>
        <mesh
          filename="package://astro_description/meshes/knee_3.STL" />
      </geometry>
      <material
        name="">
        <color
          rgba="0.615686274509804 0.811764705882353 0.929411764705882 1" />
      </material>
    </visual>
    <collision>
      <origin
        xyz="0 0 0"
        rpy="0 0 0" />
      <geometry>
        <mesh
          filename="package://astro_description/meshes/knee_3.STL" />
      </geometry>
    </collision>
  </link>
  <joint
    name="knee_3"
    type="revolute">
    <origin
      xyz="0 0.0315 -0.1875"
      rpy="0 0 0" />
    <parent
      link="shoulder_3" />
    <child
      link="knee_3" />
    <axis
      xyz="0 -1 0" />
    <limit
      lower="-3.14"
      upper="3.14"
      effort="10"
      velocity="10" />
  </joint>
  <link
    name="toe_3">
    <inertial>
      <origin
        xyz="2.95606317202157E-11 9.95770133016549E-12 -0.00105178196616634"
        rpy="0 0 0" />
      <mass
        value="0.00341340894922415" />
      <inertia
        ixx="1.37512731322582E-07"
        ixy="3.15030124015844E-16"
        ixz="-8.6213951994743E-16"
        iyy="1.34732164237532E-07"
        iyz="-2.80019546781306E-16"
        izz="1.56709984508881E-07" />
    </inertial>
    <visual>
      <origin
        xyz="0 0 0"
        rpy="0 0 0" />
      <geometry>
        <mesh
          filename="package://astro_description/meshes/toe_3.STL" />
      </geometry>
      <material
        name="">
        <color
          rgba="1 0 0 1" />
      </material>
    </visual>
    <collision>
      <origin
        xyz="0 0 0"
        rpy="0 0 0" />
      <geometry>
        <mesh
          filename="package://astro_description/meshes/toe_3.STL" />
      </geometry>
    </collision>
  </link>
  <joint
    name="toe_3"
    type="fixed">
    <origin
      xyz="0 0 -0.19"
      rpy="0 0 0" />
    <parent
      link="knee_3" />
    <child
      link="toe_3" />
    <axis
      xyz="0 0 0" />
  </joint>

  <transmission name="trans_hip_0">
      <type>transmission_interface/SimpleTransmission</type>
      <joint name="hip_0">
        <hardwareInterface>hardware_interface/EffortJointInterface</hardwareInterface>
      </joint>
      <actuator name="motor_hip_0">
        <hardwareInterface>hardware_interface/EffortJointInterface</hardwareInterface>
        <mechanicalReduction>1</mechanicalReduction>
      </actuator>
  </transmission>

 <transmission name="trans_shoulder_0">
      <type>transmission_interface/SimpleTransmission</type>
      <joint name="shoulder_0">
        <hardwareInterface>hardware_interface/EffortJointInterface</hardwareInterface>
      </joint>
      <actuator name="motor_shoulder_0">
        <hardwareInterface>hardware_interface/EffortJointInterface</hardwareInterface>
        <mechanicalReduction>1</mechanicalReduction>
      </actuator>
  </transmission>

<transmission name="trans_knee_0">
      <type>transmission_interface/SimpleTransmission</type>
      <joint name="knee_0">
        <hardwareInterface>hardware_interface/EffortJointInterface</hardwareInterface>
      </joint>
      <actuator name="motor_knee_0">
        <hardwareInterface>hardware_interface/EffortJointInterface</hardwareInterface>
        <mechanicalReduction>1</mechanicalReduction>
      </actuator>
  </transmission>

<transmission name="trans_hip_1">
      <type>transmission_interface/SimpleTransmission</type>
      <joint name="hip_1">
        <hardwareInterface>hardware_interface/EffortJointInterface</hardwareInterface>
      </joint>
      <actuator name="motor_hip_1">
        <hardwareInterface>hardware_interface/EffortJointInterface</hardwareInterface>
        <mechanicalReduction>1</mechanicalReduction>
      </actuator>
  </transmission>

 <transmission name="trans_shoulder_1">
      <type>transmission_interface/SimpleTransmission</type>
      <joint name="shoulder_1">
        <hardwareInterface>hardware_interface/EffortJointInterface</hardwareInterface>
      </joint>
      <actuator name="motor_shoulder_1">
        <hardwareInterface>hardware_interface/EffortJointInterface</hardwareInterface>
        <mechanicalReduction>1</mechanicalReduction>
      </actuator>
  </transmission>

<transmission name="trans_knee_1">
      <type>transmission_interface/SimpleTransmission</type>
      <joint name="knee_1">
        <hardwareInterface>hardware_interface/EffortJointInterface</hardwareInterface>
      </joint>
      <actuator name="motor_knee_1">
        <hardwareInterface>hardware_interface/EffortJointInterface</hardwareInterface>
        <mechanicalReduction>1</mechanicalReduction>
      </actuator>
  </transmission>

<transmission name="trans_hip_2">
      <type>transmission_interface/SimpleTransmission</type>
      <joint name="hip_2">
        <hardwareInterface>hardware_interface/EffortJointInterface</hardwareInterface>
      </joint>
      <actuator name="motor_hip_2">
        <hardwareInterface>hardware_interface/EffortJointInterface</hardwareInterface>
        <mechanicalReduction>1</mechanicalReduction>
      </actuator>
  </transmission>

 <transmission name="trans_shoulder_2">
      <type>transmission_interface/SimpleTransmission</type>
      <joint name="shoulder_2">
        <hardwareInterface>hardware_interface/EffortJointInterface</hardwareInterface>
      </joint>
      <actuator name="motor_shoulder_2">
        <hardwareInterface>hardware_interface/EffortJointInterface</hardwareInterface>
        <mechanicalReduction>1</mechanicalReduction>
      </actuator>
  </transmission>

<transmission name="trans_knee_2">
      <type>transmission_interface/SimpleTransmission</type>
      <joint name="knee_2">
        <hardwareInterface>hardware_interface/EffortJointInterface</hardwareInterface>
      </joint>
      <actuator name="motor_knee_2">
        <hardwareInterface>hardware_interface/EffortJointInterface</hardwareInterface>
        <mechanicalReduction>1</mechanicalReduction>
      </actuator>
  </transmission>

<transmission name="trans_hip_3">
      <type>transmission_interface/SimpleTransmission</type>
      <joint name="hip_3">
        <hardwareInterface>hardware_interface/EffortJointInterface</hardwareInterface>
      </joint>
      <actuator name="motor_hip_3">
        <hardwareInterface>hardware_interface/EffortJointInterface</hardwareInterface>
        <mechanicalReduction>1</mechanicalReduction>
      </actuator>
  </transmission>

 <transmission name="trans_shoulder_3">
      <type>transmission_interface/SimpleTransmission</type>
      <joint name="shoulder_3">
        <hardwareInterface>hardware_interface/EffortJointInterface</hardwareInterface>
      </joint>
      <actuator name="motor_shoulder_3">
        <hardwareInterface>hardware_interface/EffortJointInterface</hardwareInterface>
        <mechanicalReduction>1</mechanicalReduction>
      </actuator>
  </transmission>

<transmission name="trans_knee_3">
      <type>transmission_interface/SimpleTransmission</type>
      <joint name="knee_3">
        <hardwareInterface>hardware_interface/EffortJointInterface</hardwareInterface>
      </joint>
      <actuator name="motor_knee_3">
        <hardwareInterface>hardware_interface/EffortJointInterface</hardwareInterface>
        <mechanicalReduction>1</mechanicalReduction>
      </actuator>
  </transmission>

  <gazebo>
    <plugin name="gazebo_ros_control" filename="libgazebo_ros_control.so">
      <robotNamespace>/astro</robotNamespace>
      <robotSimType>gazebo_ros_control/DefaultRobotHWSim</robotSimType>
      <legacyModeNS>true</legacyModeNS>
    </plugin>
  </gazebo>
</robot>