<?xml version="1.0" encoding="utf-8"?>

<robot name="astro">
<link name="body_1">
<inertial>
<origin xyz="0 0 0" rpy="0 0 0" />
<mass value="1e-9" />
<inertia ixx="0" ixy="0" ixz="0" iyy="0" iyz="0" izz="0" />
</inertial>
</link>
<link name="body_1_0_body">
<visual>
<geometry>
<mesh filename="package://astro_description/meshes/body.stl"/>
</geometry>
<material name="body_1_0_body_material">
<color rgba="0.615686 0.811765 0.929412 1.0"/>
</material>
</visual>
<collision>
<geometry>
<mesh filename="package://astro_description/meshes/body.stl"/>
</geometry>
<material name="body_1_0_body_material">
<color rgba="0.615686 0.811765 0.929412 1.0"/>
</material>
</collision>
<inertial>
<origin xyz="3.23514e-17 -1.57563e-17 7.22909e-19" rpy="0 0 0"/>
<mass value="5.53043"/>
<inertia ixx="0.0182567" ixy="0"  ixz="0" iyy="0.039027" iyz="0" izz="0.0489361" />
</inertial>
</link>
<joint name="body_1_body_1_0_body_fixing" type="fixed">
<origin xyz="0.0659972 -0.00223125 -0.0325887" rpy="0.0869049 -2.22293e-16 -0.110998" />
<parent link="body_1" />
<child link="body_1_0_body" />
<axis xyz="0 0 0"/>
</joint>

<link name="hip_motor_1">
<inertial>
<origin xyz="0 0 0" rpy="0 0 0" />
<mass value="1e-9" />
<inertia ixx="0" ixy="0" ixz="0" iyy="0" iyz="0" izz="0" />
</inertial>
</link>
<link name="hip_motor_1_0_hip_motor">
<visual>
<geometry>
<mesh filename="package://astro_description/meshes/hip_motor.stl"/>
</geometry>
<material name="hip_motor_1_0_hip_motor_material">
<color rgba="0.615686 0.811765 0.929412 1.0"/>
</material>
</visual>
<collision>
<geometry>
<mesh filename="package://astro_description/meshes/hip_motor.stl"/>
</geometry>
<material name="hip_motor_1_0_hip_motor_material">
<color rgba="0.615686 0.811765 0.929412 1.0"/>
</material>
</collision>
<inertial>
<origin xyz="1.13446e-11 -2.52228e-11 5.19814e-10" rpy="0 0 0"/>
<mass value="0.290543"/>
<inertia ixx="0.000328594" ixy="-2.04303e-13"  ixz="2.49012e-14" iyy="0.000195003" iyz="-1.8485e-14" izz="0.000193353" />
</inertial>
</link>
<joint name="hip_motor_1_hip_motor_1_0_hip_motor_fixing" type="fixed">
<origin xyz="0 -0.0480708 0" rpy="7.08535e-18 7.46602e-18 1.29392e-17" />
<parent link="hip_motor_1" />
<child link="hip_motor_1_0_hip_motor" />
<axis xyz="0 0 0"/>
</joint>

<link name="upper_leg_1">
<inertial>
<origin xyz="0 0 0" rpy="0 0 0" />
<mass value="1e-9" />
<inertia ixx="0" ixy="0" ixz="0" iyy="0" iyz="0" izz="0" />
</inertial>
</link>
<link name="upper_leg_1_0_upper_leg">
<visual>
<geometry>
<mesh filename="package://astro_description/meshes/upper_leg.stl"/>
</geometry>
<material name="upper_leg_1_0_upper_leg_material">
<color rgba="0.615686 0.811765 0.929412 1.0"/>
</material>
</visual>
<collision>
<geometry>
<mesh filename="package://astro_description/meshes/upper_leg.stl"/>
</geometry>
<material name="upper_leg_1_0_upper_leg_material">
<color rgba="0.615686 0.811765 0.929412 1.0"/>
</material>
</collision>
<inertial>
<origin xyz="-0.0158653 -0.0518927 2.91082e-08" rpy="0 0 0"/>
<mass value="0.599558"/>
<inertia ixx="0.00301503" ixy="-0.000481164"  ixz="-1.17508e-10" iyy="0.00041169" iyz="-1.99021e-10" izz="0.00299142" />
</inertial>
</link>
<joint name="upper_leg_1_upper_leg_1_0_upper_leg_fixing" type="fixed">
<origin xyz="-0.0175 2.77556e-17 2.77556e-17" rpy="-5.07849e-18 -5.76165e-18 9.22476e-18" />
<parent link="upper_leg_1" />
<child link="upper_leg_1_0_upper_leg" />
<axis xyz="0 0 0"/>
</joint>

<link name="shin_1">
<inertial>
<origin xyz="0 0 0" rpy="0 0 0" />
<mass value="1e-9" />
<inertia ixx="0" ixy="0" ixz="0" iyy="0" iyz="0" izz="0" />
</inertial>
</link>
<link name="shin_1_0_shin">
<visual>
<geometry>
<mesh filename="package://astro_description/meshes/shin.stl"/>
</geometry>
<material name="shin_1_0_shin_material">
<color rgba="0.615686 0.811765 0.929412 1.0"/>
</material>
</visual>
<collision>
<geometry>
<mesh filename="package://astro_description/meshes/shin.stl"/>
</geometry>
<material name="shin_1_0_shin_material">
<color rgba="0.615686 0.811765 0.929412 1.0"/>
</material>
</collision>
<inertial>
<origin xyz="1.75032e-18 -2.35773e-05 -0.0854768" rpy="0 0 0"/>
<mass value="0.0649774"/>
<inertia ixx="0.000128996" ixy="0"  ixz="0" iyy="0.000127636" iyz="4.44939e-08" izz="5.60423e-06" />
</inertial>
</link>
<joint name="shin_1_shin_1_0_shin_fixing" type="fixed">
<origin xyz="0.01 0 2.77556e-17" rpy="4.44466e-17 -2.91026e-17 4.33682e-18" />
<parent link="shin_1" />
<child link="shin_1_0_shin" />
<axis xyz="0 0 0"/>
</joint>

<link name="shin_1_1_toe">
<visual>
<geometry>
<mesh filename="package://astro_description/meshes/toe.stl"/>
</geometry>
<material name="shin_1_1_toe_material">
<color rgba="1 0 0 1.0"/>
</material>
</visual>
<collision>
<geometry>
<mesh filename="package://astro_description/meshes/toe.stl"/>
</geometry>
<material name="shin_1_1_toe_material">
<color rgba="1 0 0 1.0"/>
</material>
</collision>
<inertial>
<origin xyz="2.95606e-11 -9.95771e-12 0.00105178" rpy="0 0 0"/>
<mass value="0.00402782"/>
<inertia ixx="1.62265e-07" ixy="-3.71722e-16"  ixz="1.01732e-15" iyy="1.58984e-07" iyz="-3.30423e-16" izz="1.84918e-07" />
</inertial>
</link>
<joint name="shin_1_shin_1_1_toe_fixing" type="fixed">
<origin xyz="0.01 0 -0.19" rpy="-3.14159 -1.26958e-14 1.5708" />
<parent link="shin_1" />
<child link="shin_1_1_toe" />
<axis xyz="0 0 0"/>
</joint>

<joint name="knee_9" type="revolute">
<origin xyz="-0.059 -0.1875 -1.66533e-16" rpy="3.14159 5.61294e-16 -1.5846e-15" />
<parent link="upper_leg_1" />
<child link="shin_1" />
<axis xyz="-1 0 0"/>
<limit effort="1.5" lower="-3.14" upper="3.14" velocity="22" />
<joint_properties friction="0.0"/>
</joint>

<joint name="hip_flexion_8" type="revolute">
<origin xyz="-0.0175 -0.0480708 -3.46945e-17" rpy="1.91986 6.38524e-16 1.61754e-16" />
<parent link="hip_motor_1" />
<child link="upper_leg_1" />
<axis xyz="-1 0 0"/>
<limit effort="1.5" lower="-3.14" upper="3.14" velocity="22" />
<joint_properties friction="0.0"/>
</joint>

<joint name="hip_abduction_7" type="revolute">
<origin xyz="0.304807 0.0363077 -0.0269469" rpy="-1.53545e-15 0.349452 -1.68179" />
<parent link="body_1" />
<child link="hip_motor_1" />
<axis xyz="0 -1 0"/>
<limit effort="1.5" lower="-3.14" upper="3.14" velocity="22" />
<joint_properties friction="0.0"/>
</joint>

<link name="hip_motor_2">
<inertial>
<origin xyz="0 0 0" rpy="0 0 0" />
<mass value="1e-9" />
<inertia ixx="0" ixy="0" ixz="0" iyy="0" iyz="0" izz="0" />
</inertial>
</link>
<link name="hip_motor_2_0_hip_motor">
<visual>
<geometry>
<mesh filename="package://astro_description/meshes/hip_motor.stl"/>
</geometry>
<material name="hip_motor_2_0_hip_motor_material">
<color rgba="0.615686 0.811765 0.929412 1.0"/>
</material>
</visual>
<collision>
<geometry>
<mesh filename="package://astro_description/meshes/hip_motor.stl"/>
</geometry>
<material name="hip_motor_2_0_hip_motor_material">
<color rgba="0.615686 0.811765 0.929412 1.0"/>
</material>
</collision>
<inertial>
<origin xyz="1.13446e-11 -2.52228e-11 5.19814e-10" rpy="0 0 0"/>
<mass value="0.290543"/>
<inertia ixx="0.000328594" ixy="-2.04303e-13"  ixz="2.49012e-14" iyy="0.000195003" iyz="-1.8485e-14" izz="0.000193353" />
</inertial>
</link>
<joint name="hip_motor_2_hip_motor_2_0_hip_motor_fixing" type="fixed">
<origin xyz="0 0.0480708 0" rpy="-3.94366e-19 -6.42774e-17 -5.68311e-18" />
<parent link="hip_motor_2" />
<child link="hip_motor_2_0_hip_motor" />
<axis xyz="0 0 0"/>
</joint>

<link name="upper_leg_2">
<inertial>
<origin xyz="0 0 0" rpy="0 0 0" />
<mass value="1e-9" />
<inertia ixx="0" ixy="0" ixz="0" iyy="0" iyz="0" izz="0" />
</inertial>
</link>
<link name="upper_leg_2_0_upper_leg">
<visual>
<geometry>
<mesh filename="package://astro_description/meshes/upper_leg.stl"/>
</geometry>
<material name="upper_leg_2_0_upper_leg_material">
<color rgba="0.615686 0.811765 0.929412 1.0"/>
</material>
</visual>
<collision>
<geometry>
<mesh filename="package://astro_description/meshes/upper_leg.stl"/>
</geometry>
<material name="upper_leg_2_0_upper_leg_material">
<color rgba="0.615686 0.811765 0.929412 1.0"/>
</material>
</collision>
<inertial>
<origin xyz="-0.0158653 -0.0518927 2.91082e-08" rpy="0 0 0"/>
<mass value="0.599558"/>
<inertia ixx="0.00301503" ixy="-0.000481164"  ixz="-1.17508e-10" iyy="0.00041169" iyz="-1.99021e-10" izz="0.00299142" />
</inertial>
</link>
<joint name="upper_leg_2_upper_leg_2_0_upper_leg_fixing" type="fixed">
<origin xyz="0.03783 6.93889e-18 0" rpy="-2.85189e-18 1.61614e-17 3.69393e-17" />
<parent link="upper_leg_2" />
<child link="upper_leg_2_0_upper_leg" />
<axis xyz="0 0 0"/>
</joint>

<link name="shin_2">
<inertial>
<origin xyz="0 0 0" rpy="0 0 0" />
<mass value="1e-9" />
<inertia ixx="0" ixy="0" ixz="0" iyy="0" iyz="0" izz="0" />
</inertial>
</link>
<link name="shin_2_0_toe">
<visual>
<geometry>
<mesh filename="package://astro_description/meshes/toe.stl"/>
</geometry>
<material name="shin_2_0_toe_material">
<color rgba="1 0 0 1.0"/>
</material>
</visual>
<collision>
<geometry>
<mesh filename="package://astro_description/meshes/toe.stl"/>
</geometry>
<material name="shin_2_0_toe_material">
<color rgba="1 0 0 1.0"/>
</material>
</collision>
<inertial>
<origin xyz="2.95606e-11 -9.95771e-12 0.00105178" rpy="0 0 0"/>
<mass value="0.00402782"/>
<inertia ixx="1.62265e-07" ixy="-3.71722e-16"  ixz="1.01732e-15" iyy="1.58984e-07" iyz="-3.30423e-16" izz="1.84918e-07" />
</inertial>
</link>
<joint name="shin_2_shin_2_0_toe_fixing" type="fixed">
<origin xyz="0.007525 0 -0.19" rpy="3.14159 9.50014e-19 1.5708" />
<parent link="shin_2" />
<child link="shin_2_0_toe" />
<axis xyz="0 0 0"/>
</joint>

<link name="shin_2_1_shin">
<visual>
<geometry>
<mesh filename="package://astro_description/meshes/shin.stl"/>
</geometry>
<material name="shin_2_1_shin_material">
<color rgba="0.615686 0.811765 0.929412 1.0"/>
</material>
</visual>
<collision>
<geometry>
<mesh filename="package://astro_description/meshes/shin.stl"/>
</geometry>
<material name="shin_2_1_shin_material">
<color rgba="0.615686 0.811765 0.929412 1.0"/>
</material>
</collision>
<inertial>
<origin xyz="1.75032e-18 -2.35773e-05 -0.0854768" rpy="0 0 0"/>
<mass value="0.0649774"/>
<inertia ixx="0.000128996" ixy="0"  ixz="0" iyy="0.000127636" iyz="4.44939e-08" izz="5.60423e-06" />
</inertial>
</link>
<joint name="shin_2_shin_2_1_shin_fixing" type="fixed">
<origin xyz="0.007525 -2.77556e-17 0" rpy="-8.20438e-18 -1.48504e-17 -4.83794e-17" />
<parent link="shin_2" />
<child link="shin_2_1_shin" />
<axis xyz="0 0 0"/>
</joint>

<joint name="knee_6" type="revolute">
<origin xyz="-0.001195 -0.1875 -2.498e-16" rpy="3.09586 -1.58941e-17 3.17485e-17" />
<parent link="upper_leg_2" />
<child link="shin_2" />
<axis xyz="-1 0 0"/>
<limit effort="1.5" lower="-3.14" upper="3.14" velocity="22" />
<joint_properties friction="0.0"/>
</joint>

<joint name="hip_flexion_5" type="revolute">
<origin xyz="0.07283 0.0480708 2.08167e-17" rpy="-1.58401 2.09646e-16 -3.14159" />
<parent link="hip_motor_2" />
<child link="upper_leg_2" />
<axis xyz="-1 0 0"/>
<limit effort="1.5" lower="-3.14" upper="3.14" velocity="22" />
<joint_properties friction="0.0"/>
</joint>

<joint name="hip_abduction_4" type="revolute">
<origin xyz="-0.158466 0.0879422 -0.0269469" rpy="3.14159 -0.249989 1.4598" />
<parent link="body_1" />
<child link="hip_motor_2" />
<axis xyz="0 -1 0"/>
<limit effort="1.5" lower="-3.14" upper="3.14" velocity="22" />
<joint_properties friction="0.0"/>
</joint>

<link name="hip_motor_3">
<inertial>
<origin xyz="0 0 0" rpy="0 0 0" />
<mass value="1e-9" />
<inertia ixx="0" ixy="0" ixz="0" iyy="0" iyz="0" izz="0" />
</inertial>
</link>
<link name="hip_motor_3_0_hip_motor">
<visual>
<geometry>
<mesh filename="package://astro_description/meshes/hip_motor.stl"/>
</geometry>
<material name="hip_motor_3_0_hip_motor_material">
<color rgba="0.615686 0.811765 0.929412 1.0"/>
</material>
</visual>
<collision>
<geometry>
<mesh filename="package://astro_description/meshes/hip_motor.stl"/>
</geometry>
<material name="hip_motor_3_0_hip_motor_material">
<color rgba="0.615686 0.811765 0.929412 1.0"/>
</material>
</collision>
<inertial>
<origin xyz="1.13446e-11 -2.52228e-11 5.19814e-10" rpy="0 0 0"/>
<mass value="0.290543"/>
<inertia ixx="0.000328594" ixy="-2.04303e-13"  ixz="2.49012e-14" iyy="0.000195003" iyz="-1.8485e-14" izz="0.000193353" />
</inertial>
</link>
<joint name="hip_motor_3_hip_motor_3_0_hip_motor_fixing" type="fixed">
<origin xyz="0 0.0480708 -3.46945e-18" rpy="-3.87128e-18 2.22688e-17 9.68802e-18" />
<parent link="hip_motor_3" />
<child link="hip_motor_3_0_hip_motor" />
<axis xyz="0 0 0"/>
</joint>

<link name="upper_leg_3">
<inertial>
<origin xyz="0 0 0" rpy="0 0 0" />
<mass value="1e-9" />
<inertia ixx="0" ixy="0" ixz="0" iyy="0" iyz="0" izz="0" />
</inertial>
</link>
<link name="upper_leg_3_0_upper_leg">
<visual>
<geometry>
<mesh filename="package://astro_description/meshes/upper_leg.stl"/>
</geometry>
<material name="upper_leg_3_0_upper_leg_material">
<color rgba="0.615686 0.811765 0.929412 1.0"/>
</material>
</visual>
<collision>
<geometry>
<mesh filename="package://astro_description/meshes/upper_leg.stl"/>
</geometry>
<material name="upper_leg_3_0_upper_leg_material">
<color rgba="0.615686 0.811765 0.929412 1.0"/>
</material>
</collision>
<inertial>
<origin xyz="-0.0158653 -0.0518927 2.91082e-08" rpy="0 0 0"/>
<mass value="0.599558"/>
<inertia ixx="0.00301503" ixy="-0.000481164"  ixz="-1.17508e-10" iyy="0.00041169" iyz="-1.99021e-10" izz="0.00299142" />
</inertial>
</link>
<joint name="upper_leg_3_upper_leg_3_0_upper_leg_fixing" type="fixed">
<origin xyz="-0.0175 0 0" rpy="1.50341e-17 -5.27038e-18 1.87504e-17" />
<parent link="upper_leg_3" />
<child link="upper_leg_3_0_upper_leg" />
<axis xyz="0 0 0"/>
</joint>

<link name="shin_3">
<inertial>
<origin xyz="0 0 0" rpy="0 0 0" />
<mass value="1e-9" />
<inertia ixx="0" ixy="0" ixz="0" iyy="0" iyz="0" izz="0" />
</inertial>
</link>
<link name="shin_3_0_shin">
<visual>
<geometry>
<mesh filename="package://astro_description/meshes/shin.stl"/>
</geometry>
<material name="shin_3_0_shin_material">
<color rgba="0.615686 0.811765 0.929412 1.0"/>
</material>
</visual>
<collision>
<geometry>
<mesh filename="package://astro_description/meshes/shin.stl"/>
</geometry>
<material name="shin_3_0_shin_material">
<color rgba="0.615686 0.811765 0.929412 1.0"/>
</material>
</collision>
<inertial>
<origin xyz="1.75032e-18 -2.35773e-05 -0.0854768" rpy="0 0 0"/>
<mass value="0.0649774"/>
<inertia ixx="0.000128996" ixy="0"  ixz="0" iyy="0.000127636" iyz="4.44939e-08" izz="5.60423e-06" />
</inertial>
</link>
<joint name="shin_3_shin_3_0_shin_fixing" type="fixed">
<origin xyz="-0.01 0 0" rpy="7.8451e-19 2.00255e-17 -1.0127e-17" />
<parent link="shin_3" />
<child link="shin_3_0_shin" />
<axis xyz="0 0 0"/>
</joint>

<link name="shin_3_1_toe">
<visual>
<geometry>
<mesh filename="package://astro_description/meshes/toe.stl"/>
</geometry>
<material name="shin_3_1_toe_material">
<color rgba="1 0 0 1.0"/>
</material>
</visual>
<collision>
<geometry>
<mesh filename="package://astro_description/meshes/toe.stl"/>
</geometry>
<material name="shin_3_1_toe_material">
<color rgba="1 0 0 1.0"/>
</material>
</collision>
<inertial>
<origin xyz="2.95606e-11 -9.95771e-12 0.00105178" rpy="0 0 0"/>
<mass value="0.00402782"/>
<inertia ixx="1.62265e-07" ixy="-3.71722e-16"  ixz="1.01732e-15" iyy="1.58984e-07" iyz="-3.30423e-16" izz="1.84918e-07" />
</inertial>
</link>
<joint name="shin_3_shin_3_1_toe_fixing" type="fixed">
<origin xyz="-0.01 -2.77556e-17 -0.19" rpy="-3.14159 -8.66018e-15 1.5708" />
<parent link="shin_3" />
<child link="shin_3_1_toe" />
<axis xyz="0 0 0"/>
</joint>

<joint name="knee_3" type="revolute">
<origin xyz="-0.059 -0.1875 -2.08167e-16" rpy="0.224792 6.77349e-18 -3.14159" />
<parent link="upper_leg_3" />
<child link="shin_3" />
<axis xyz="-1 0 0"/>
<limit effort="1.5" lower="-3.14" upper="3.14" velocity="22" />
<joint_properties friction="0.0"/>
</joint>

<joint name="hip_flexion_2" type="revolute">
<origin xyz="0.0175 0.0480708 -6.93889e-18" rpy="1.46167 -2.94281e-16 3.14159" />
<parent link="hip_motor_3" />
<child link="upper_leg_3" />
<axis xyz="-1 0 0"/>
<limit effort="1.5" lower="-3.14" upper="3.14" velocity="22" />
<joint_properties friction="0.0"/>
</joint>

<joint name="hip_abduction_1" type="revolute">
<origin xyz="-0.172812 -0.0407702 -0.0382304" rpy="2.10258e-16 0.262942 -1.68179" />
<parent link="body_1" />
<child link="hip_motor_3" />
<axis xyz="0 -1 0"/>
<limit effort="1.5" lower="-3.14" upper="3.14" velocity="22" />
<joint_properties friction="0.0"/>
</joint>

<link name="hip_motor_4">
<inertial>
<origin xyz="0 0 0" rpy="0 0 0" />
<mass value="1e-9" />
<inertia ixx="0" ixy="0" ixz="0" iyy="0" iyz="0" izz="0" />
</inertial>
</link>
<link name="hip_motor_4_0_hip_motor">
<visual>
<geometry>
<mesh filename="package://astro_description/meshes/hip_motor.stl"/>
</geometry>
<material name="hip_motor_4_0_hip_motor_material">
<color rgba="0.615686 0.811765 0.929412 1.0"/>
</material>
</visual>
<collision>
<geometry>
<mesh filename="package://astro_description/meshes/hip_motor.stl"/>
</geometry>
<material name="hip_motor_4_0_hip_motor_material">
<color rgba="0.615686 0.811765 0.929412 1.0"/>
</material>
</collision>
<inertial>
<origin xyz="1.13446e-11 -2.52228e-11 5.19814e-10" rpy="0 0 0"/>
<mass value="0.290543"/>
<inertia ixx="0.000328594" ixy="-2.04303e-13"  ixz="2.49012e-14" iyy="0.000195003" iyz="-1.8485e-14" izz="0.000193353" />
</inertial>
</link>
<joint name="hip_motor_4_hip_motor_4_0_hip_motor_fixing" type="fixed">
<origin xyz="0 -0.0480708 8.23994e-18" rpy="-1.0701e-17 -1.09953e-16 8.37824e-18" />
<parent link="hip_motor_4" />
<child link="hip_motor_4_0_hip_motor" />
<axis xyz="0 0 0"/>
</joint>

<link name="upper_leg_4">
<inertial>
<origin xyz="0 0 0" rpy="0 0 0" />
<mass value="1e-9" />
<inertia ixx="0" ixy="0" ixz="0" iyy="0" iyz="0" izz="0" />
</inertial>
</link>
<link name="upper_leg_4_0_upper_leg">
<visual>
<geometry>
<mesh filename="package://astro_description/meshes/upper_leg.stl"/>
</geometry>
<material name="upper_leg_4_0_upper_leg_material">
<color rgba="0.615686 0.811765 0.929412 1.0"/>
</material>
</visual>
<collision>
<geometry>
<mesh filename="package://astro_description/meshes/upper_leg.stl"/>
</geometry>
<material name="upper_leg_4_0_upper_leg_material">
<color rgba="0.615686 0.811765 0.929412 1.0"/>
</material>
</collision>
<inertial>
<origin xyz="-0.0158653 -0.0518927 2.91082e-08" rpy="0 0 0"/>
<mass value="0.599558"/>
<inertia ixx="0.00301503" ixy="-0.000481164"  ixz="-1.17508e-10" iyy="0.00041169" iyz="-1.99021e-10" izz="0.00299142" />
</inertial>
</link>
<joint name="upper_leg_4_upper_leg_4_0_upper_leg_fixing" type="fixed">
<origin xyz="0.010165 -1.0842e-18 0" rpy="5.13508e-18 1.0553e-17 2.019e-17" />
<parent link="upper_leg_4" />
<child link="upper_leg_4_0_upper_leg" />
<axis xyz="0 0 0"/>
</joint>

<link name="shin_4">
<inertial>
<origin xyz="0 0 0" rpy="0 0 0" />
<mass value="1e-9" />
<inertia ixx="0" ixy="0" ixz="0" iyy="0" iyz="0" izz="0" />
</inertial>
</link>
<link name="shin_4_0_shin">
<visual>
<geometry>
<mesh filename="package://astro_description/meshes/shin.stl"/>
</geometry>
<material name="shin_4_0_shin_material">
<color rgba="0.615686 0.811765 0.929412 1.0"/>
</material>
</visual>
<collision>
<geometry>
<mesh filename="package://astro_description/meshes/shin.stl"/>
</geometry>
<material name="shin_4_0_shin_material">
<color rgba="0.615686 0.811765 0.929412 1.0"/>
</material>
</collision>
<inertial>
<origin xyz="1.75032e-18 -2.35773e-05 -0.0854768" rpy="0 0 0"/>
<mass value="0.0649774"/>
<inertia ixx="0.000128996" ixy="0"  ixz="0" iyy="0.000127636" iyz="4.44939e-08" izz="5.60423e-06" />
</inertial>
</link>
<joint name="shin_4_shin_4_0_shin_fixing" type="fixed">
<origin xyz="-0.007525 0 0" rpy="-1.41386e-18 1.68235e-17 -1.73211e-17" />
<parent link="shin_4" />
<child link="shin_4_0_shin" />
<axis xyz="0 0 0"/>
</joint>

<link name="shin_4_1_toe">
<visual>
<geometry>
<mesh filename="package://astro_description/meshes/toe.stl"/>
</geometry>
<material name="shin_4_1_toe_material">
<color rgba="1 0 0 1.0"/>
</material>
</visual>
<collision>
<geometry>
<mesh filename="package://astro_description/meshes/toe.stl"/>
</geometry>
<material name="shin_4_1_toe_material">
<color rgba="1 0 0 1.0"/>
</material>
</collision>
<inertial>
<origin xyz="2.95606e-11 -9.95771e-12 0.00105178" rpy="0 0 0"/>
<mass value="0.00402782"/>
<inertia ixx="1.62265e-07" ixy="-3.71722e-16"  ixz="1.01732e-15" iyy="1.58984e-07" iyz="-3.30423e-16" izz="1.84918e-07" />
</inertial>
</link>
<joint name="shin_4_shin_4_1_toe_fixing" type="fixed">
<origin xyz="-0.007525 8.32667e-17 -0.19" rpy="3.14159 1.43116e-18 1.5708" />
<parent link="shin_4" />
<child link="shin_4_1_toe" />
<axis xyz="0 0 0"/>
</joint>

<joint name="knee_12" type="revolute">
<origin xyz="-0.02886 -0.1875 -1.66533e-16" rpy="0.0146175 1.46111e-15 3.14159" />
<parent link="upper_leg_4" />
<child link="shin_4" />
<axis xyz="-1 0 0"/>
<limit effort="1.5" lower="-3.14" upper="3.14" velocity="22" />
<joint_properties friction="0.0"/>
</joint>

<joint name="hip_flexion_11" type="revolute">
<origin xyz="0.045165 -0.0480708 -1.23599e-17" rpy="1.5708 -4.73516e-16 -3.14159" />
<parent link="hip_motor_4" />
<child link="upper_leg_4" />
<axis xyz="-1 0 0"/>
<limit effort="1.5" lower="-3.14" upper="3.14" velocity="22" />
<joint_properties friction="0.0"/>
</joint>

<joint name="hip_abduction_10" type="revolute">
<origin xyz="0.290461 -0.0924047 -0.0382304" rpy="2.76452e-16 0.584224 -1.68179" />
<parent link="body_1" />
<child link="hip_motor_4" />
<axis xyz="0 -1 0"/>
<limit effort="1.5" lower="-3.14" upper="3.14" velocity="22" />
<joint_properties friction="0.0"/>
</joint>

</robot>
